import time
from mcpi.minecraft import Minecraft
from mcpi import block

mc = Minecraft.create()

#mc.player.setPos(0,0,0)
#mc.postToChat("CLEAR AN AREA WITH AIR TO BUILD")
air = 0
#mc.setBlocks(-19,0,-19,19,64,19,air)
x, y, z = mc.player.getPos()
x = x+5
mc.setBlocks(x,y,z, x+8,y+8,z+8,air)
mc.setBlocks(x,y,z, x+7,y+7,z+7,24,2)
mc.setBlocks(x+3,y,z, x+7,y+7,z+7,5)
mc.setBlocks(x,y+4,z, x+7,y+7,z+7,5)
mc.setBlock(x,y+4,z+2,24,2)
mc.setBlock(x,y+4,z+5,24,2)
mc.setBlocks(x,y+2,z+1, x,y+3,z+1,35,15)
mc.setBlocks(x,y+2,z+6, x,y+3,z+6,35,15)
mc.setBlock(x,y+3,z+3,35,12)
mc.setBlocks(x,y+3,z, x+1,y+3,z,35,12)
mc.setBlocks(x+2,y+1,z, x+2,y+2,z,35,12)
mc.setBlocks(x,y+3,z+7, x+1,y+3,z+7,35,12)
mc.setBlocks(x+2,y+1,z+7, x+2,y+2,z+7,35,12)
mc.setBlocks(x+3,y,z, x+7,y,z,35,12)
mc.setBlocks(x+7,y,z, x+3,y,z+7,35,12)
mc.setBlocks(x+3,y,z+7, x+7,y,z+7,35,12)
mc.setBlock(x+4,y+1,z,35,12)
mc.setBlock(x+4,y+1,z+7,35,12)
mc.setBlock(x+7,y+1,z+2,35,12)
mc.setBlock(x+7,y+1,z+5,35,12)
mc.setBlocks(x+7,y,z, x+7,y+2,z,35,12)
mc.setBlocks(x+7,y,z+7, x+7,y+2,z+7,35,12)
mc.setBlock(x,y+3,z+3,35,12)
mc.setBlocks(x,y+7,z, x+7,y+7,z,35,12)
mc.setBlocks(x+7,y+7,z, x+7,y+7,z+7,35,12)
mc.setBlocks(x,y+7,z+7, x+7,y+7,z+7,35,12)
mc.setBlock(x+7,y+7,z+2,35,12)
mc.setBlock(x+7,y+7,z+6,35,12)
mc.setBlock(x,y+7,z+6,35,12)
mc.setBlocks(x+7,y+7,z+7, x+7,y+5,z+7,35,12)
mc.setBlocks(x+7,y+7,z, x+7,y+5,z,35,12)
mc.setBlock(x+4,y+6,z+7,35,12)
mc.setBlock(x+4,y+6,z,35,12)
mc.setBlocks(x+2,y+7,z, x+2,y+4,z,35,12)
mc.setBlocks(x+2,y+7,z+7, x+2,y+4,z+7,35,12)
mc.setBlocks(x+2,y+7,z+7, x+2,y+4,z+7,35,12)
mc.setBlock(x+1,y+5,z,35,12)
mc.setBlock(x+1,y+5,z+7,35,12)
mc.setBlock(x,y+4,z+1,35,12)
mc.setBlock(x+7,y+6,z+2,35,12)
mc.setBlock(x+7,y+6,z+5,35,12)
mc.setBlock(x+3,y+3,z,35,12)
mc.setBlock(x+3,y+3,z+7,35,12)
mc.setBlock(x,y+6,z,35,12)
mc.setBlock(x,y+6,z+7,35,12)
